<?xml version="1.0" ?>
<!-- =================================================================================== -->
<!-- |    This document was autogenerated by xacro from cr35ia.xacro                   | -->
<!-- |    EDITING THIS FILE BY HAND IS NOT RECOMMENDED                                 | -->
<!-- =================================================================================== -->
<robot name="fanuc_cr35ia" xmlns:xacro="http://ros.org/wiki/xacro">
  <!-- RAL 1021: Rape yellow -->
  <!-- RAL 9002: Grey white -->
  <!-- RAL 7024: Graphite grey -->
  <!-- Roboguide colours -->
  <!-- #3D3D3D -->
  <!-- #474747 -->
  <!-- #4F4F4F -->
  <!-- #666666 -->
  <!-- #FFFF00 -->
  <!-- #BAB0B0 -->
  <!-- #E6E6E6 -->
  <!-- #00FF73: 'collaborative green' -->
  <!-- approximations -->
  <!-- Pi, the ratio of a circle's circumference to its diameter -->
  <!-- Pi divided by two -->
  <!-- Pi divided by four -->
  <!-- links -->
  <link name="base_link">
    <visual>
      <origin rpy="0 0 0" xyz="0 0 0"/>
      <geometry>
        <mesh filename="package://fanuc_cr35ia_support/meshes/cr35ia/visual/base_link.stl"/>
      </geometry>
      <material name="">
        <color rgba="0.278431372549 0.278431372549 0.278431372549 1.0"/>
      </material>
    </visual>
    <collision>
      <origin rpy="0 0 0" xyz="0 0 0"/>
      <geometry>
        <mesh filename="package://fanuc_cr35ia_support/meshes/cr35ia/collision/base_link.stl"/>
      </geometry>
    </collision>
  </link>
  <link name="link_1">
    <visual>
      <origin rpy="0 0 0" xyz="0 0 0"/>
      <geometry>
        <mesh filename="package://fanuc_cr35ia_support/meshes/cr35ia/visual/link_1.stl"/>
      </geometry>
      <material name="">
        <color rgba="0.0 0.607843137255 0.274509803922 1.0"/>
      </material>
    </visual>
    <collision>
      <origin rpy="0 0 0" xyz="0 0 0"/>
      <geometry>
        <mesh filename="package://fanuc_cr35ia_support/meshes/cr35ia/collision/link_1.stl"/>
      </geometry>
    </collision>
  </link>
  <link name="link_2">
    <visual>
      <origin rpy="0 0 0" xyz="0 0 0"/>
      <geometry>
        <mesh filename="package://fanuc_cr35ia_support/meshes/cr35ia/visual/link_2.stl"/>
      </geometry>
      <material name="">
        <color rgba="0.0 0.607843137255 0.274509803922 1.0"/>
      </material>
    </visual>
    <collision>
      <origin rpy="0 0 0" xyz="0 0 0"/>
      <geometry>
        <mesh filename="package://fanuc_cr35ia_support/meshes/cr35ia/collision/link_2.stl"/>
      </geometry>
    </collision>
  </link>
  <link name="link_3">
    <visual>
      <origin rpy="0 0 0" xyz="0 0 0"/>
      <geometry>
        <mesh filename="package://fanuc_cr35ia_support/meshes/cr35ia/visual/link_3.stl"/>
      </geometry>
      <material name="">
        <color rgba="0.0 0.607843137255 0.274509803922 1.0"/>
      </material>
    </visual>
    <collision>
      <origin rpy="0 0 0" xyz="0 0 0"/>
      <geometry>
        <mesh filename="package://fanuc_cr35ia_support/meshes/cr35ia/collision/link_3.stl"/>
      </geometry>
    </collision>
  </link>
  <link name="link_4">
    <visual>
      <origin rpy="0 0 0" xyz="0 0 0"/>
      <geometry>
        <mesh filename="package://fanuc_cr35ia_support/meshes/cr35ia/visual/link_4.stl"/>
      </geometry>
      <material name="">
        <color rgba="0.0 0.607843137255 0.274509803922 1.0"/>
      </material>
    </visual>
    <collision>
      <origin rpy="0 0 0" xyz="0 0 0"/>
      <geometry>
        <mesh filename="package://fanuc_cr35ia_support/meshes/cr35ia/collision/link_4.stl"/>
      </geometry>
    </collision>
  </link>
  <link name="link_5">
    <visual>
      <origin rpy="0 0 0" xyz="0 0 0"/>
      <geometry>
        <mesh filename="package://fanuc_cr35ia_support/meshes/cr35ia/visual/link_5.stl"/>
      </geometry>
      <material name="">
        <color rgba="0.86 0.85 0.81 1.0"/>
      </material>
    </visual>
    <collision>
      <origin rpy="0 0 0" xyz="0 0 0"/>
      <geometry>
        <mesh filename="package://fanuc_cr35ia_support/meshes/cr35ia/collision/link_5.stl"/>
      </geometry>
    </collision>
  </link>
  <link name="link_6">
    <visual>
      <origin rpy="0 0 0" xyz="0 0 0"/>
      <geometry>
        <mesh filename="package://fanuc_cr35ia_support/meshes/cr35ia/visual/link_6.stl"/>
      </geometry>
      <material name="">
        <color rgba="0.15 0.15 0.15 1.0"/>
      </material>
    </visual>
    <collision>
      <origin rpy="0 0 0" xyz="0 0 0"/>
      <geometry>
        <mesh filename="package://fanuc_cr35ia_support/meshes/cr35ia/collision/link_6.stl"/>
      </geometry>
    </collision>
  </link>
  <link name="tool0"/>
  <!-- joints -->
  <joint name="joint_1" type="revolute">
    <origin rpy="0 0 0" xyz="0 0 1.180"/>
    <parent link="base_link"/>
    <child link="link_1"/>
    <axis xyz="0 0 1"/>
    <limit effort="0" lower="-2.9670" upper="2.9670" velocity="3.1415"/>
  </joint>
  <joint name="joint_2" type="revolute">
    <origin rpy="0 0 0" xyz="0.150 0 0"/>
    <parent link="link_1"/>
    <child link="link_2"/>
    <axis xyz="0 1 0"/>
    <!-- refer to note 1 in the package manifest -->
    <limit effort="0" lower="-0.7853" upper="2.0943" velocity="3.1415"/>
  </joint>
  <joint name="joint_3" type="revolute">
    <origin rpy="0 0 0" xyz="0 0 0.790"/>
    <parent link="link_2"/>
    <child link="link_3"/>
    <axis xyz="0 -1 0"/>
    <!-- refer to note 1 in the package manifest -->
    <limit effort="0" lower="-2.1450" upper="2.3561" velocity="3.4906"/>
  </joint>
  <joint name="joint_4" type="revolute">
    <origin rpy="0 0 0" xyz="0 0 0.150"/>
    <parent link="link_3"/>
    <child link="link_4"/>
    <axis xyz="-1 0 0"/>
    <limit effort="0" lower="-3.4906" upper="3.4906" velocity="6.1086"/>
  </joint>
  <joint name="joint_5" type="revolute">
    <origin rpy="0 0 0" xyz="0.860 0 0"/>
    <parent link="link_4"/>
    <child link="link_5"/>
    <axis xyz="0 -1 0"/>
    <limit effort="0" lower="-1.9198" upper="1.9198" velocity="6.1086"/>
  </joint>
  <joint name="joint_6" type="revolute">
    <origin rpy="0 0 0" xyz="0.100 0 0"/>
    <parent link="link_5"/>
    <child link="link_6"/>
    <axis xyz="-1 0 0"/>
    <limit effort="0" lower="-7.8539" upper="7.8539" velocity="6.9813"/>
  </joint>
  <joint name="joint_6-tool0" type="fixed">
    <origin rpy="3.1415926535 -1.570796327 0" xyz="0 0 0"/>
    <parent link="link_6"/>
    <child link="tool0"/>
  </joint>
  <!-- ROS base_link to Fanuc World Coordinates transform -->
  <link name="base"/>
  <joint name="base_link-base" type="fixed">
    <origin rpy="0 0 0" xyz="0 0 1.180"/>
    <parent link="base_link"/>
    <child link="base"/>
  </joint>
</robot>

