<?xml version="1.0" ?>
<robot xmlns:xacro="http://ros.org/wiki/xacro">
	<xacro:include filename="$(find fanuc_assets)/urdf/common_materials.xacro"/>

	<xacro:macro name="fanuc_m16ib20" params="prefix">
		<!-- links -->
		<link name="${prefix}base_link">
			<visual>
				<origin xyz="0 0 0" rpy="0 0 0"/>
				<geometry>
					<mesh filename="package://fanuc_m16ib_support/meshes/m16ib20/visual/base_link.stl"/>
				</geometry>
				<xacro:material_fanuc_yellow />
			</visual>
			<collision>
				<origin xyz="0 0 0" rpy="0 0 0"/>
				<geometry>
					<mesh filename="package://fanuc_m16ib_support/meshes/m16ib20/collision/base_link.stl"/>
				</geometry>
			</collision>
		</link>
		<link name="${prefix}link_1">
			<visual>
				<origin xyz="0 0 0" rpy="0 0 0"/>
				<geometry>
					<mesh filename="package://fanuc_m16ib_support/meshes/m16ib20/visual/link_1.stl"/>
				</geometry>
				<xacro:material_fanuc_yellow />
			</visual>
			<collision>
				<origin xyz="0 0 0" rpy="0 0 0"/>
				<geometry>
					<mesh filename="package://fanuc_m16ib_support/meshes/m16ib20/collision/link_1.stl"/>
				</geometry>
			</collision>
		</link>
		<link name="${prefix}link_2">
			<visual>
				<origin xyz="0 0 0" rpy="0 0 0"/>
				<geometry>
					<mesh filename="package://fanuc_m16ib_support/meshes/m16ib20/visual/link_2.stl"/>
				</geometry>
				<xacro:material_fanuc_yellow />
			</visual>
			<collision>
				<origin xyz="0 0 0" rpy="0 0 0"/>
				<geometry>
					<mesh filename="package://fanuc_m16ib_support/meshes/m16ib20/collision/link_2.stl"/>
				</geometry>
			</collision>
		</link>
		<link name="${prefix}link_3">
			<visual>
				<origin xyz="0 0 0" rpy="0 0 0"/>
				<geometry>
					<mesh filename="package://fanuc_m16ib_support/meshes/m16ib20/visual/link_3.stl"/>
				</geometry>
				<xacro:material_fanuc_yellow />
			</visual>
			<collision>
				<origin xyz="0 0 0" rpy="0 0 0"/>
				<geometry>
					<mesh filename="package://fanuc_m16ib_support/meshes/m16ib20/collision/link_3.stl"/>
				</geometry>
			</collision>
		</link>
		<link name="${prefix}link_4">
			<visual>
				<origin xyz="0 0 0" rpy="0 0 0"/>
				<geometry>
					<mesh filename="package://fanuc_m16ib_support/meshes/m16ib20/visual/link_4.stl"/>
				</geometry>
				<xacro:material_fanuc_yellow />
			</visual>
			<collision>
				<origin xyz="0 0 0" rpy="0 0 0"/>
				<geometry>
					<mesh filename="package://fanuc_m16ib_support/meshes/m16ib20/collision/link_4.stl"/>
				</geometry>
			</collision>
		</link>
		<link name="${prefix}link_5">
			<visual>
				<origin xyz="0 0 0" rpy="0 0 0"/>
				<geometry>
					<mesh filename="package://fanuc_m16ib_support/meshes/m16ib20/visual/link_5.stl"/>
				</geometry>
				<xacro:material_fanuc_yellow />
			</visual>
			<collision>
				<origin xyz="0 0 0" rpy="0 0 0"/>
				<geometry>
					<mesh filename="package://fanuc_m16ib_support/meshes/m16ib20/collision/link_5.stl"/>
				</geometry>
			</collision>
		</link>
		<link name="${prefix}link_6">
			<visual>
				<origin xyz="0 0 0" rpy="0 0 0"/>
				<geometry>
					<mesh filename="package://fanuc_m16ib_support/meshes/m16ib20/visual/link_6.stl"/>
				</geometry>
				<xacro:material_fanuc_black />
			</visual>
			<collision>
				<origin xyz="0 0 0" rpy="0 0 0"/>
				<geometry>
					<mesh filename="package://fanuc_m16ib_support/meshes/m16ib20/collision/link_6.stl"/>
				</geometry>
			</collision>
		</link>
		<link name="${prefix}tool0"/>

		<!-- joints -->
		<joint name="${prefix}joint_1" type="revolute">
			<origin xyz="0 0 0.245" rpy="0 0 0"/>
			<parent link="${prefix}base_link"/>
			<child link="${prefix}link_1"/>
			<axis xyz="0 0 1"/>
			<limit lower="-2.967" upper="2.967" effort="0" velocity="2.879"/>
		</joint>
		<joint name="${prefix}joint_2" type="revolute">
			<origin xyz="0.15 0.18759 0.28" rpy="0 0 0"/>
			<parent link="${prefix}link_1"/>
			<child link="${prefix}link_2"/>
			<axis xyz="0 1 0"/>
			<limit lower="-1.38" upper="2.78" effort="0" velocity="2.879"/>
		</joint>
		<joint name="${prefix}joint_3" type="revolute">
			<origin xyz="0 -0.18759 0.77" rpy="0 0 0"/>
			<parent link="${prefix}link_2"/>
			<child link="${prefix}link_3"/>
			<axis xyz="0 -1 0"/>
			<limit lower="-4.08" upper="1.38" effort="0" velocity="3.054"/>
		</joint>
		<joint name="${prefix}joint_4" type="revolute">
			<origin xyz="0.18425 0 0.1" rpy="0 0 0"/>
			<parent link="${prefix}link_3"/>
			<child link="${prefix}link_4"/>
			<axis xyz="-1 0 0"/>
			<limit lower="-3.48" upper="3.48" effort="0" velocity="6.108"/>
		</joint>
		<joint name="${prefix}joint_5" type="revolute">
			<origin xyz="0.55575 0 0" rpy="0 0 0"/>
			<parent link="${prefix}link_4"/>
			<child link="${prefix}link_5"/>
			<axis xyz="0 -1 0"/>
			<limit lower="-2.43" upper="2.43" effort="0" velocity="5.934"/>
		</joint>
		<joint name="${prefix}joint_6" type="revolute">
			<origin xyz="0.1 0 0" rpy="0 0 0"/>
			<parent link="${prefix}link_5"/>
			<child link="${prefix}link_6"/>
			<axis xyz="-1 0 0"/>
			<limit lower="-7.84" upper="7.84" effort="0" velocity="9.075"/>
		</joint>
		<joint name="${prefix}joint_6-tool0" type="fixed">
			<parent link="${prefix}link_6"/>
			<child link="${prefix}tool0"/>
			<origin xyz="0 0 0" rpy="0 0 0"/>
		</joint>
	</xacro:macro>
</robot>
