<robot
  name="">
  <link
    name="base_link">
    <inertial>
      <origin
        xyz="0 0.0022695 0.52668"
        rpy="0 0 0" />
      <mass
        value="637.75" />
      <inertia
        ixx="386.78"
        ixy="-1.6196"
        ixz="19.276"
        iyy="396.53"
        iyz="-2.6647"
        izz="362.82" />
    </inertial>
    <visual>
      <origin
        xyz="0 0 0"
        rpy="0 0 0" />
      <geometry>
        <mesh
          filename="package://M10iA/meshes/base_link.STL" />
      </geometry>
      <material
        name="">
        <color
          rgba="0.75294 0.75294 0.75294 1" />
      </material>
    </visual>
    <collision>
      <origin
        xyz="0 0 0"
        rpy="0 0 0" />
      <geometry>
        <mesh
          filename="package://M10iA/meshes/base_link.STL" />
      </geometry>
    </collision>
  </link>
  <link
    name="link_1">
    <inertial>
      <origin
        xyz="0.069243 0.0022695 0.52668"
        rpy="0 0 0" />
      <mass
        value="637.75" />
      <inertia
        ixx="386.78"
        ixy="-1.6196"
        ixz="19.276"
        iyy="396.53"
        iyz="-2.6647"
        izz="362.82" />
    </inertial>
    <visual>
      <origin
        xyz="0 0 0"
        rpy="0 0 0" />
      <geometry>
        <mesh
          filename="package://M10iA/meshes/link_1.STL" />
      </geometry>
      <material
        name="">
        <color
          rgba="0.75294 0.75294 0 1" />
      </material>
    </visual>
    <collision>
      <origin
        xyz="0 0 0"
        rpy="0 0 0" />
      <geometry>
        <mesh
          filename="package://M10iA/meshes/link_1.STL" />
      </geometry>
    </collision>
  </link>
  <joint
    name="joint_joint_1"
    type="revolute">
    <origin
      xyz="0 0 0"
      rpy="1.5708 0 0" />
    <parent
      link="base_link" />
    <child
      link="link_1" />
    <axis
      xyz="0 0 1" />
    <limit
      lower="-3.14"
      upper="3.14"
      effort="0"
      velocity="0" />
    <calibration
      rising="0"
      falling="0" />
    <dynamics
      damping="0"
      friction="0" />
    <safety_controller
      soft_lower_limit="0"
      soft_upper_limit="0"
      k_position="0"
      k_velocity="0" />
  </joint>
  <link
    name="link_2">
    <inertial>
      <origin
        xyz="-0.080757 0.04227 0.076679"
        rpy="0 0 0" />
      <mass
        value="637.75" />
      <inertia
        ixx="386.78"
        ixy="-1.6196"
        ixz="19.276"
        iyy="396.53"
        iyz="-2.6647"
        izz="362.82" />
    </inertial>
    <visual>
      <origin
        xyz="0 0 0"
        rpy="0 0 0" />
      <geometry>
        <mesh
          filename="package://M10iA/meshes/link_2.STL" />
      </geometry>
      <material
        name="">
        <color
          rgba="0.75294 0.75294 0 1" />
      </material>
    </visual>
    <collision>
      <origin
        xyz="0 0 0"
        rpy="0 0 0" />
      <geometry>
        <mesh
          filename="package://M10iA/meshes/link_2.STL" />
      </geometry>
    </collision>
  </link>
  <joint
    name="joint_joint_2"
    type="revolute">
    <origin
      xyz="0.15 -0.04 0.45"
      rpy="0 0 0" />
    <parent
      link="link_1" />
    <child
      link="link_2" />
    <axis
      xyz="0 1 0" />
    <limit
      lower="-3.14"
      upper="3.14"
      effort="0"
      velocity="3.14" />
    <calibration
      rising="0"
      falling="0" />
    <dynamics
      damping="0"
      friction="0" />
    <safety_controller
      soft_lower_limit="0"
      soft_upper_limit="0"
      k_position="0"
      k_velocity="0" />
  </joint>
  <link
    name="link_3">
    <inertial>
      <origin
        xyz="-0.080757 0.06477 -0.52332"
        rpy="0 0 0" />
      <mass
        value="637.75" />
      <inertia
        ixx="386.78"
        ixy="-1.6196"
        ixz="19.276"
        iyy="396.53"
        iyz="-2.6647"
        izz="362.82" />
    </inertial>
    <visual>
      <origin
        xyz="0 0 0"
        rpy="0 0 0" />
      <geometry>
        <mesh
          filename="package://M10iA/meshes/link_3.STL" />
      </geometry>
      <material
        name="">
        <color
          rgba="0.75294 0.75294 0 1" />
      </material>
    </visual>
    <collision>
      <origin
        xyz="0 0 0"
        rpy="0 0 0" />
      <geometry>
        <mesh
          filename="package://M10iA/meshes/link_3.STL" />
      </geometry>
    </collision>
  </link>
  <joint
    name="joint_joint_3"
    type="revolute">
    <origin
      xyz="0 -0.0225 0.6"
      rpy="0 0 0" />
    <parent
      link="link_2" />
    <child
      link="link_3" />
    <axis
      xyz="0 1 0" />
    <limit
      lower="-4.2"
      upper="4.2"
      effort="0"
      velocity="4.2" />
    <calibration
      rising="0"
      falling="0" />
    <dynamics
      damping="0"
      friction="0" />
    <safety_controller
      soft_lower_limit="0"
      soft_upper_limit="0"
      k_position="0"
      k_velocity="0" />
  </joint>
  <link
    name="link_4">
    <inertial>
      <origin
        xyz="-0.26126 0.0022695 -0.72332"
        rpy="0 0 0" />
      <mass
        value="637.75" />
      <inertia
        ixx="386.78"
        ixy="-1.6196"
        ixz="19.276"
        iyy="396.53"
        iyz="-2.6647"
        izz="362.82" />
    </inertial>
    <visual>
      <origin
        xyz="0 0 0"
        rpy="0 0 0" />
      <geometry>
        <mesh
          filename="package://M10iA/meshes/link_4.STL" />
      </geometry>
      <material
        name="">
        <color
          rgba="0.75294 0.75294 0 1" />
      </material>
    </visual>
    <collision>
      <origin
        xyz="0 0 0"
        rpy="0 0 0" />
      <geometry>
        <mesh
          filename="package://M10iA/meshes/link_4.STL" />
      </geometry>
    </collision>
  </link>
  <joint
    name="joint_joint_4"
    type="revolute">
    <origin
      xyz="0.1805 0.0625 0.2"
      rpy="0 0 0" />
    <parent
      link="link_3" />
    <child
      link="link_4" />
    <axis
      xyz="1 0 0" />
    <limit
      lower="-3.14"
      upper="3.14"
      effort="0"
      velocity="3.14" />
    <calibration
      rising="0"
      falling="0" />
    <dynamics
      damping="0"
      friction="0" />
    <safety_controller
      soft_lower_limit="0"
      soft_upper_limit="0"
      k_position="0"
      k_velocity="0" />
  </joint>
  <link
    name="link_5">
    <inertial>
      <origin
        xyz="-0.72076 0.05877 -0.72332"
        rpy="0 0 0" />
      <mass
        value="637.75" />
      <inertia
        ixx="386.78"
        ixy="-1.6196"
        ixz="19.276"
        iyy="396.53"
        iyz="-2.6647"
        izz="362.82" />
    </inertial>
    <visual>
      <origin
        xyz="0 0 0"
        rpy="0 0 0" />
      <geometry>
        <mesh
          filename="package://M10iA/meshes/link_5.STL" />
      </geometry>
      <material
        name="">
        <color
          rgba="0.75294 0.75294 0 1" />
      </material>
    </visual>
    <collision>
      <origin
        xyz="0 0 0"
        rpy="0 0 0" />
      <geometry>
        <mesh
          filename="package://M10iA/meshes/link_5.STL" />
      </geometry>
    </collision>
  </link>
  <joint
    name="joint_joint_5"
    type="revolute">
    <origin
      xyz="0.4595 -0.0565 0"
      rpy="0 0 0" />
    <parent
      link="link_4" />
    <child
      link="link_5" />
    <axis
      xyz="0 1 0" />
    <limit
      lower="-3.14"
      upper="3.14"
      effort="0"
      velocity="6.25" />
    <calibration
      rising="0"
      falling="0" />
    <dynamics
      damping="0"
      friction="0" />
    <safety_controller
      soft_lower_limit="0"
      soft_upper_limit="0"
      k_position="0"
      k_velocity="0" />
  </joint>
  <link
    name="link_6">
    <inertial>
      <origin
        xyz="-0.82076 0.0022695 -0.72332"
        rpy="0 0 0" />
      <mass
        value="637.75" />
      <inertia
        ixx="386.78"
        ixy="-1.6196"
        ixz="19.276"
        iyy="396.53"
        iyz="-2.6647"
        izz="362.82" />
    </inertial>
    <visual>
      <origin
        xyz="0 0 0"
        rpy="0 0 0" />
      <geometry>
        <mesh
          filename="package://M10iA/meshes/link_6.STL" />
      </geometry>
      <material
        name="">
        <color
          rgba="0.75294 0.75294 0 1" />
      </material>
    </visual>
    <collision>
      <origin
        xyz="0 0 0"
        rpy="0 0 0" />
      <geometry>
        <mesh
          filename="package://M10iA/meshes/link_6.STL" />
      </geometry>
    </collision>
  </link>
  <joint
    name="joint_joint_6"
    type="revolute">
    <origin
      xyz="0.1 0.0565 0"
      rpy="0 0 0" />
    <parent
      link="link_5" />
    <child
      link="link_6" />
    <axis
      xyz="1 0 0" />
    <limit
      lower="-6.28"
      upper="6.28"
      effort="0"
      velocity="6.28" />
    <calibration
      rising="0"
      falling="0" />
    <dynamics
      damping="0"
      friction="0" />
    <safety_controller
      soft_lower_limit="0"
      soft_upper_limit="0"
      k_position="0"
      k_velocity="0" />
  </joint>
</robot>