<?xml version="1.0" ?>
<!-- =================================================================================== -->
<!-- |    This document was autogenerated by xacro from M16iB20.xacro                  | -->
<!-- |    EDITING THIS FILE BY HAND IS NOT RECOMMENDED                                 | -->
<!-- =================================================================================== -->
<robot name="M16iB20" xmlns:xacro="http://ros.org/wiki/xacro">
  <link name="base_link">
    <inertial>
      <origin rpy="0 0 0" xyz="0 9.68920591007408E-05 0.538248432765216"/>
      <mass value="48654.354928172"/>
      <inertia ixx="51563.7946245021" ixy="0.552841467322453" ixz="-212.267889356987" iyy="49495.9076886951" iyz="1.80688027777408" izz="54368.3241585813"/>
    </inertial>
    <visual>
      <origin rpy="0 0 0" xyz="0 0 0"/>
      <geometry>
        <mesh filename="package://fanuc_config/meshes/m_16iB20/visual/base_link.STL"/>
      </geometry>
      <material name="">
        <color rgba="1 1 0 1"/>
      </material>
    </visual>
    <collision>
      <origin rpy="0 0 0" xyz="0 0 0"/>
      <geometry>
        <mesh filename="package://fanuc_config/meshes/m_16iB20/collision/base_link.STL"/>
      </geometry>
    </collision>
  </link>
  <link name="Link_1">
    <inertial>
      <origin rpy="0 0 0" xyz="0.0335399435995477 9.68920591007463E-05 0.293476071945811"/>
      <mass value="48654.354928172"/>
      <inertia ixx="51563.7946245021" ixy="0.552841467322453" ixz="-212.267889356987" iyy="49495.9076886951" iyz="1.80688027777408" izz="54368.3241585813"/>
    </inertial>
    <visual>
      <origin rpy="0 0 0" xyz="0 0 0"/>
      <geometry>
        <mesh filename="package://fanuc_config/meshes/m_16iB20/visual/Link_1.STL"/>
      </geometry>
      <material name="">
        <color rgba="1 1 0 1"/>
      </material>
    </visual>
    <collision>
      <origin rpy="0 0 0" xyz="0 0 0"/>
      <geometry>
        <mesh filename="package://fanuc_config/meshes/m_16iB20/collision/Link_1.STL"/>
      </geometry>
    </collision>
  </link>
  <link name="Link_2">
    <inertial>
      <origin rpy="0 0 0" xyz="-0.116459985096576 -0.187496105761522 0.0134762050463809"/>
      <mass value="48654.354928172"/>
      <inertia ixx="51563.7946245021" ixy="0.552841467322453" ixz="-212.267889356987" iyy="49495.9076886951" iyz="1.80688027777408" izz="54368.3241585813"/>
    </inertial>
    <visual>
      <origin rpy="0 0 0" xyz="0 0 0"/>
      <geometry>
        <mesh filename="package://fanuc_config/meshes/m_16iB20/visual/Link_2.STL"/>
      </geometry>
      <material name="">
        <color rgba="1 1 0 1"/>
      </material>
    </visual>
    <collision>
      <origin rpy="0 0 0" xyz="0 0 0"/>
      <geometry>
        <mesh filename="package://fanuc_config/meshes/m_16iB20/collision/Link_2.STL"/>
      </geometry>
    </collision>
  </link>
  <link name="Link_3">
    <inertial>
      <origin rpy="0 0 0" xyz="-0.116459985097232 0.000649393837860671 -0.7565234388513"/>
      <mass value="48654.354928172"/>
      <inertia ixx="51563.7946245021" ixy="0.552841467322453" ixz="-212.267889356987" iyy="49495.9076886951" iyz="1.80688027777408" izz="54368.3241585813"/>
    </inertial>
    <visual>
      <origin rpy="0 0 0" xyz="0 0 0"/>
      <geometry>
        <mesh filename="package://fanuc_config/meshes/m_16iB20/visual/Link_3.STL"/>
      </geometry>
      <material name="">
        <color rgba="1 1 0 1"/>
      </material>
    </visual>
    <collision>
      <origin rpy="0 0 0" xyz="0 0 0"/>
      <geometry>
        <mesh filename="package://fanuc_config/meshes/m_16iB20/collision/Link_3.STL"/>
      </geometry>
    </collision>
  </link>
  <link name="Link_4">
    <inertial>
      <origin rpy="0 0 0" xyz="-0.301157421773673 0.000649393837861561 -0.856523437562654"/>
      <mass value="48654.354928172"/>
      <inertia ixx="51563.7946245021" ixy="0.552841467322453" ixz="-212.267889356987" iyy="49495.9076886951" iyz="1.80688027777408" izz="54368.3241585813"/>
    </inertial>
    <visual>
      <origin rpy="0 0 0" xyz="0 0 0"/>
      <geometry>
        <mesh filename="package://fanuc_config/meshes/m_16iB20/visual/Link_4.STL"/>
      </geometry>
      <material name="">
        <color rgba="1 1 0 1"/>
      </material>
    </visual>
    <collision>
      <origin rpy="0 0 0" xyz="0 0 0"/>
      <geometry>
        <mesh filename="package://fanuc_config/meshes/m_16iB20/collision/Link_4.STL"/>
      </geometry>
    </collision>
  </link>
  <link name="Link_5">
    <inertial>
      <origin rpy="0 0 0" xyz="-0.856906936709003 0.000456131051686355 -0.857257705801685"/>
      <mass value="48654.354928172"/>
      <inertia ixx="51563.7946245021" ixy="0.552841467322453" ixz="-212.267889356987" iyy="49495.9076886951" iyz="1.80688027777408" izz="54368.3241585813"/>
    </inertial>
    <visual>
      <origin rpy="0 0 0" xyz="0 0 0"/>
      <geometry>
        <mesh filename="package://fanuc_config/meshes/m_16iB20/visual/Link_5.STL"/>
      </geometry>
      <material name="">
        <color rgba="1 1 0 1"/>
      </material>
    </visual>
    <collision>
      <origin rpy="0 0 0" xyz="0 0 0"/>
      <geometry>
        <mesh filename="package://fanuc_config/meshes/m_16iB20/collision/Link_5.STL"/>
      </geometry>
    </collision>
  </link>
  <link name="Link_6">
    <inertial>
      <origin rpy="0 0 0" xyz="-0.957051849301239 0.000456131051686355 -0.857390019418947"/>
      <mass value="48654.354928172"/>
      <inertia ixx="51563.7946245021" ixy="0.552841467322453" ixz="-212.267889356987" iyy="49495.9076886951" iyz="1.80688027777408" izz="54368.3241585813"/>
    </inertial>
    <visual>
      <origin rpy="0 0 0" xyz="0 0 0"/>
      <geometry>
        <mesh filename="package://fanuc_config/meshes/m_16iB20/visual/Link_6.STL"/>
      </geometry>
      <material name="">
        <color rgba="1 1 0 1"/>
      </material>
    </visual>
    <collision>
      <origin rpy="0 0 0" xyz="0 0 0"/>
      <geometry>
        <mesh filename="package://fanuc_config/meshes/m_16iB20/collision/Link_6.STL"/>
      </geometry>
    </collision>
  </link>
  <link name="tool0"/>
  <joint name="Joint_1" type="revolute">
    <origin rpy="0 0 0" xyz="0 0 0.24477"/>
    <parent link="base_link"/>
    <child link="Link_1"/>
    <axis xyz="0 0 1"/>
    <limit effort="0" lower="-2.967" upper="2.967" velocity="0"/>
    <calibration falling="0" rising="0"/>
    <dynamics damping="0" friction="0"/>
    <!--safety_controller
		      soft_lower_limit="0"
		      soft_upper_limit="0"
		      k_position="0"
		      k_velocity="0" /-->
  </joint>
  <joint name="Joint_2" type="revolute">
    <origin rpy="0 0 0" xyz="0.15 0.18759 0.28"/>
    <parent link="Link_1"/>
    <child link="Link_2"/>
    <axis xyz="0 -1 0"/>
    <limit effort="0" lower="-1.5708" upper="1.9" velocity="0"/>
    <calibration falling="0" rising="0"/>
    <dynamics damping="0" friction="0"/>
    <!--safety_controller
		      soft_lower_limit="0"
		      soft_upper_limit="0"
		      k_position="0"
		      k_velocity="0" /-->
  </joint>
  <joint name="Joint_3" type="revolute">
    <origin rpy="0 0 0" xyz="0 -0.18815 0.77"/>
    <parent link="Link_2"/>
    <child link="Link_3"/>
    <axis xyz="0 1 0"/>
    <limit effort="0" lower="-4.21" upper="1.45" velocity="0"/>
    <calibration falling="0" rising="0"/>
    <dynamics damping="0" friction="0"/>
    <!--safety_controller
		      soft_lower_limit="0"
		      soft_upper_limit="0"
		      k_position="0"
		      k_velocity="0" /-->
  </joint>
  <joint name="Joint_4" type="revolute">
    <origin rpy="0 0 0" xyz="0.1847 0 0.1"/>
    <parent link="Link_3"/>
    <child link="Link_4"/>
    <axis xyz="-1 0 -0.0013212"/>
    <limit effort="0" lower="-3.4907" upper="3.4907" velocity="0"/>
    <calibration falling="0" rising="0"/>
    <dynamics damping="0" friction="0"/>
    <!--safety_controller
		      soft_lower_limit="0"
		      soft_upper_limit="0"
		      k_position="0"
		      k_velocity="0" /-->
  </joint>
  <joint name="Joint_5" type="revolute">
    <origin rpy="0 0 0" xyz="0.55575 0.00019326 0.00073427"/>
    <parent link="Link_4"/>
    <child link="Link_5"/>
    <axis xyz="0 1 0"/>
    <limit effort="0" lower="-2.4435" upper="2.4435" velocity="0"/>
    <calibration falling="0" rising="0"/>
    <dynamics damping="0" friction="0"/>
    <!--safety_controller
		      soft_lower_limit="0"
		      soft_upper_limit="0"
		      k_position="0"
		      k_velocity="0" /-->
  </joint>
  <joint name="Joint_6" type="revolute">
    <origin rpy="0 0 0" xyz="0.10014 0 0.00013231"/>
    <parent link="Link_5"/>
    <child link="Link_6"/>
    <axis xyz="-1 0 -0.0013212"/>
    <limit effort="0" lower="-7.85398" upper="7.85398" velocity="0"/>
    <calibration falling="0" rising="0"/>
    <dynamics damping="0" friction="0"/>
    <!--safety_controller
		      soft_lower_limit="0"
		      soft_upper_limit="0"
		      k_position="0"
		      k_velocity="0" /-->
  </joint>
  <joint name="Joint_6-tool0" type="fixed">
    <parent link="Link_6"/>
    <child link="tool0"/>
    <origin rpy="0 0 0" xyz="0 0 0"/>
  </joint>
</robot>

