<?xml version="1.0"?>
<robot xmlns:xacro="http://ros.org/wiki/xacro">
	<xacro:macro name="m430ia2f" params="prefix">


		<!-- links -->
		<link name="${prefix}base_link">
			<visual>
				<origin xyz="0 0 0" rpy="0 0 0"/>
				<geometry>
					<mesh filename="package://fanuc_config/meshes/m430ia2f/visual/base_link.stl"/>
				</geometry>
				<material name="white">
					<color rgba="1 1 1 1"/>
				</material>
			</visual>
			<collision>
				<origin xyz="0 0 0" rpy="0 0 0"/>
				<geometry>
					<mesh filename="package://fanuc_config/meshes/m430ia2f/collision/base_link.stl"/>
				</geometry>
			</collision>
		</link>
		<link name="${prefix}link_1">
			<visual>
				<origin xyz="0 0 0" rpy="0 0 0"/>
				<geometry>
					<mesh filename="package://fanuc_config/meshes/m430ia2f/visual/link_1.stl"/>
				</geometry>
				<material name="">
					<color rgba="0.89804 0.89804 0.89804 1"/>
				</material>
			</visual>
			<collision>
				<origin xyz="0 0 0" rpy="0 0 0"/>
				<geometry>
					<mesh filename="package://fanuc_config/meshes/m430ia2f/collision/link_1.stl"/>
				</geometry>
			</collision>
		</link>
		<link name="${prefix}link_2">
			<visual>
				<origin xyz="0 0 0" rpy="0 0 0"/>
				<geometry>
					<mesh filename="package://fanuc_config/meshes/m430ia2f/visual/link_2.stl"/>
				</geometry>
				<material name="">
					<color rgba="0.89804 0.89804 0.89804 1"/>
				</material>
			</visual>
			<collision>
				<origin xyz="0 0 0" rpy="0 0 0"/>
				<geometry>
					<mesh filename="package://fanuc_config/meshes/m430ia2f/collision/link_2.stl"/>
				</geometry>
			</collision>
		</link>
		<link name="${prefix}link_3">
			<visual>
				<origin xyz="0 0 0.053" rpy="0 0 0"/>
				<geometry>
					<mesh filename="package://fanuc_config/meshes/m430ia2f/visual/link_3.stl"/>
				</geometry>
				<material name="">
					<color rgba="0.89804 0.89804 0.89804 1"/>
				</material>
			</visual>
			<collision>
				<origin xyz="0 0 0.053" rpy="0 0 0"/>
				<geometry>
					<mesh filename="package://fanuc_config/meshes/m430ia2f/collision/link_3.stl"/>
				</geometry>
			</collision>
		</link>
		<link name="${prefix}link_4">
			<visual>
				<origin xyz="0 0 0" rpy="0 0 0"/>
				<geometry>
					<mesh filename="package://fanuc_config/meshes/m430ia2f/visual/link_4.stl"/>
				</geometry>
				<material name="">
					<color rgba="0.89804 0.89804 0.89804 1"/>
				</material>
			</visual>
			<collision>
				<origin xyz="0 0 0" rpy="0 0 0"/>
				<geometry>
					<mesh filename="package://fanuc_config/meshes/m430ia2f/collision/link_4.stl"/>
				</geometry>
			</collision>
		</link>
		<link name="${prefix}link_5">
			<visual>
				<origin xyz="0 0 0" rpy="0 0 0"/>
				<geometry>
					<mesh filename="package://fanuc_config/meshes/m430ia2f/visual/link_5.stl"/>
				</geometry>
				<material name="">
					<color rgba="0.75294 0.75294 0.75294 1"/>
				</material>
			</visual>
			<collision>
				<origin xyz="0 0 0" rpy="0 0 0"/>
				<geometry>
					<mesh filename="package://fanuc_config/meshes/m430ia2f/collision/link_5.stl"/>
				</geometry>
			</collision>
		</link>
		<link name="${prefix}tool0"/>


		<!-- joints -->
		<joint name="${prefix}joint_1" type="revolute">
			<origin xyz="-6.0758E-19 1.2493E-16 0.44" rpy="0 0 0"/>
			<parent link="${prefix}base_link"/>
			<child link="${prefix}link_1"/>
			<axis xyz="0 0 1"/>
			<limit lower="-3.1415" upper="3.1415" effort="0" velocity="5.23598775598"/>
		</joint>
		<joint name="${prefix}joint_2" type="revolute">
			<origin xyz="-1.4097E-17 0.171 -4.4409E-16" rpy="0 0 0"/>
			<parent link="${prefix}link_1"/>
			<child link="${prefix}link_2"/>
			<axis xyz="0 1 0"/>
			<limit lower="-2.00707" upper="2.00707" effort="0" velocity="5.58505360638"/>
		</joint>
		<joint name="${prefix}joint_3" type="revolute">
			<!-- origin xyz="1.2197E-19 -0.171 0.403" rpy="0 0 0" / -->
			<origin xyz="1.2197E-19 -0.171 0.350" rpy="0 0 0"/>
			<parent link="${prefix}link_2"/>
			<child link="${prefix}link_3"/>
			<axis xyz="0 1 0"/>
			<limit lower="-1.771457" upper="1.771457" effort="0" velocity="5.58505360638"/>
		</joint>
		<joint name="${prefix}joint_4" type="revolute">
			<!-- origin xyz="-2.6075E-17 -0.06 0.497" rpy="0 0 0" / -->
			<origin xyz="-2.6075E-17 -0.06 0.55" rpy="0 0 0"/>
			<parent link="${prefix}link_3"/>
			<child link="${prefix}link_4"/>
			<axis xyz="0 1 0"/>
			<limit lower="-2.617917" upper="2.617917" effort="0" velocity="6.28318530718"/>
		</joint>
		<joint name="${prefix}joint_5" type="revolute">
			<origin xyz="1.4734E-16 -0.035 0.065" rpy="0 0 0"/>
			<parent link="${prefix}link_4"/>
			<child link="${prefix}link_5"/>
			<axis xyz="0 0 1"/>
			<limit lower="-4.71225" upper="4.71225" effort="0" velocity="20.9439510239"/>
		</joint>
		<joint name="${prefix}joint_5-tool0" type="fixed">
			<parent link="${prefix}link_5"/>
			<child link="${prefix}tool0"/>
			<origin xyz="0 0 0" rpy="0 0 0"/>
		</joint>

	</xacro:macro>
</robot>
