<?xml version="1.0" ?>
<!-- =================================================================================== -->
<!-- |    This document was autogenerated by xacro from m430ia2f.xacro                 | -->
<!-- |    EDITING THIS FILE BY HAND IS NOT RECOMMENDED                                 | -->
<!-- =================================================================================== -->
<robot name="m430ia2f" xmlns:xacro="http://ros.org/wiki/xacro">
  <link name="base_link">
    <visual>
      <origin rpy="0 0 0" xyz="0 0 0"/>
      <geometry>
        <mesh filename="package://fanuc_config/meshes/m430ia2f/visual/base_link.stl"/>
      </geometry>
      <material name="white">
        <color rgba="1 1 1 1"/>
      </material>
    </visual>
    <collision>
      <origin rpy="0 0 0" xyz="0 0 0"/>
      <geometry>
        <mesh filename="package://fanuc_config/meshes/m430ia2f/collision/base_link.stl"/>
      </geometry>
    </collision>
  </link>
  <link name="link_1">
    <visual>
      <origin rpy="0 0 0" xyz="0 0 0"/>
      <geometry>
        <mesh filename="package://fanuc_config/meshes/m430ia2f/visual/link_1.stl"/>
      </geometry>
      <material name="">
        <color rgba="0.89804 0.89804 0.89804 1"/>
      </material>
    </visual>
    <collision>
      <origin rpy="0 0 0" xyz="0 0 0"/>
      <geometry>
        <mesh filename="package://fanuc_config/meshes/m430ia2f/collision/link_1.stl"/>
      </geometry>
    </collision>
  </link>
  <link name="link_2">
    <visual>
      <origin rpy="0 0 0" xyz="0 0 0"/>
      <geometry>
        <mesh filename="package://fanuc_config/meshes/m430ia2f/visual/link_2.stl"/>
      </geometry>
      <material name="">
        <color rgba="0.89804 0.89804 0.89804 1"/>
      </material>
    </visual>
    <collision>
      <origin rpy="0 0 0" xyz="0 0 0"/>
      <geometry>
        <mesh filename="package://fanuc_config/meshes/m430ia2f/collision/link_2.stl"/>
      </geometry>
    </collision>
  </link>
  <link name="link_3">
    <visual>
      <origin rpy="0 0 0" xyz="0 0 0.053"/>
      <geometry>
        <mesh filename="package://fanuc_config/meshes/m430ia2f/visual/link_3.stl"/>
      </geometry>
      <material name="">
        <color rgba="0.89804 0.89804 0.89804 1"/>
      </material>
    </visual>
    <collision>
      <origin rpy="0 0 0" xyz="0 0 0.053"/>
      <geometry>
        <mesh filename="package://fanuc_config/meshes/m430ia2f/collision/link_3.stl"/>
      </geometry>
    </collision>
  </link>
  <link name="link_4">
    <visual>
      <origin rpy="0 0 0" xyz="0 0 0"/>
      <geometry>
        <mesh filename="package://fanuc_config/meshes/m430ia2f/visual/link_4.stl"/>
      </geometry>
      <material name="">
        <color rgba="0.89804 0.89804 0.89804 1"/>
      </material>
    </visual>
    <collision>
      <origin rpy="0 0 0" xyz="0 0 0"/>
      <geometry>
        <mesh filename="package://fanuc_config/meshes/m430ia2f/collision/link_4.stl"/>
      </geometry>
    </collision>
  </link>
  <link name="link_5">
    <visual>
      <origin rpy="0 0 0" xyz="0 0 0"/>
      <geometry>
        <mesh filename="package://fanuc_config/meshes/m430ia2f/visual/link_5.stl"/>
      </geometry>
      <material name="">
        <color rgba="0.75294 0.75294 0.75294 1"/>
      </material>
    </visual>
    <collision>
      <origin rpy="0 0 0" xyz="0 0 0"/>
      <geometry>
        <mesh filename="package://fanuc_config/meshes/m430ia2f/collision/link_5.stl"/>
      </geometry>
    </collision>
  </link>
  <link name="tool0"/>
  <joint name="joint_1" type="revolute">
    <origin rpy="0 0 0" xyz="-6.0758E-19 1.2493E-16 0.44"/>
    <parent link="base_link"/>
    <child link="link_1"/>
    <axis xyz="0 0 1"/>
    <limit effort="0" lower="-3.1415" upper="3.1415" velocity="5.23598775598"/>
  </joint>
  <joint name="joint_2" type="revolute">
    <origin rpy="0 0 0" xyz="-1.4097E-17 0.171 -4.4409E-16"/>
    <parent link="link_1"/>
    <child link="link_2"/>
    <axis xyz="0 1 0"/>
    <limit effort="0" lower="-2.00707" upper="2.00707" velocity="5.58505360638"/>
  </joint>
  <joint name="joint_3" type="revolute">
    <!-- origin xyz="1.2197E-19 -0.171 0.403" rpy="0 0 0" / -->
    <origin rpy="0 0 0" xyz="1.2197E-19 -0.171 0.350"/>
    <parent link="link_2"/>
    <child link="link_3"/>
    <axis xyz="0 1 0"/>
    <limit effort="0" lower="-1.771457" upper="1.771457" velocity="5.58505360638"/>
  </joint>
  <joint name="joint_4" type="revolute">
    <!-- origin xyz="-2.6075E-17 -0.06 0.497" rpy="0 0 0" / -->
    <origin rpy="0 0 0" xyz="-2.6075E-17 -0.06 0.55"/>
    <parent link="link_3"/>
    <child link="link_4"/>
    <axis xyz="0 1 0"/>
    <limit effort="0" lower="-2.617917" upper="2.617917" velocity="6.28318530718"/>
  </joint>
  <joint name="joint_5" type="revolute">
    <origin rpy="0 0 0" xyz="1.4734E-16 -0.035 0.065"/>
    <parent link="link_4"/>
    <child link="link_5"/>
    <axis xyz="0 0 1"/>
    <limit effort="0" lower="-4.71225" upper="4.71225" velocity="20.9439510239"/>
  </joint>
  <joint name="joint_5-tool0" type="fixed">
    <parent link="link_5"/>
    <child link="tool0"/>
    <origin rpy="0 0 0" xyz="0 0 0"/>
  </joint>
</robot>

