<?xml version="1.0" ?>
<robot xmlns:xacro="http://ros.org/wiki/xacro">
	<xacro:macro name="m10iA" params="prefix">
		<!-- link list -->
		<link name="${prefix}base_link">
			<visual>
     			<origin
        		xyz="0 0 0"
       			rpy="-1.578 0 0" />
      			<geometry>
        			<mesh
          			filename="package://fanuc_config/meshes/m_10iA/visual/base_link.stl" />
      			</geometry>
      			<material
        			name="grey">
        			<color
          			rgba="0.75 0.75 0.75 1" />
      			</material>
    		</visual>
 			<collision>
     			<origin
        		xyz="0 0 0"
       			rpy="-1.578 0 0" />
				<geometry>
					<mesh filename="package://fanuc_config/meshes/m_10iA/collision/base_link.stl" />
				</geometry>
				<material name="yellow">
					<color rgba="1 1 0 1"/>
				</material>
			</collision>

		</link>
		<link name="${prefix}link_1">
			<visual>
      			<origin
        			xyz="0 0 0"
        			rpy="0 0 0" />
      			<geometry>
        			<mesh
          			filename="package://fanuc_config/meshes/m_10iA/visual/link_1.stl" />
      			</geometry>
      			<material name="grey"/>
    		</visual>
			<collision>
      			<origin
        			xyz="0 0 0"
        			rpy="0 0 0" />
				<geometry>
					<mesh filename="package://fanuc_config/meshes/m_10iA/collision/link_1.stl" />
				</geometry>
				<material name="yellow"/>
			</collision>

		</link>
		<link name="${prefix}link_2">
		    <visual>
      			<origin
        			xyz="0 0 0"
        			rpy="0 0 0" />
      			<geometry>
        			<mesh
          			filename="package://fanuc_config/meshes/m_10iA/visual/link_2.stl" />
      			</geometry>
      			<material name="grey"/>
    		</visual>
			<collision>
      			<origin
        			xyz="0 0 0"
        			rpy="0 0 0" />
				<geometry>
					<mesh filename="package://fanuc_config/meshes/m_10iA/collision/link_2.stl" />
				</geometry>
				<material name="yellow"/>
			</collision>

		</link>
		<link name="${prefix}link_3">
			<visual>
				<origin
					xyz="0 0 0"
					rpy="0 0 0" />
			  	<geometry>
					<mesh
				  	filename="package://fanuc_config/meshes/m_10iA/visual/link_3.stl" />
			  	</geometry>
			  	<material name="grey"/>
			</visual>
			<collision>
      			<origin
        			xyz="0 0 0"
        			rpy="0 0 0" />
				<geometry>
					<mesh filename="package://fanuc_config/meshes/m_10iA/collision/link_3.stl" />
				</geometry>
				<material name="yellow"/>
			</collision>

		</link>
		<link name="${prefix}link_4">
			<visual>
				  <origin
					xyz="0 0 0"
					rpy="0 0 0" />
				  <geometry>
					<mesh
					  filename="package://fanuc_config/meshes/m_10iA/visual/link_4.stl" />
				  </geometry>
				  <material name="grey"/>
			</visual>
			<collision>
      			<origin
        			xyz="0 0 0"
        			rpy="0 0 0" />
				<geometry>
					<mesh filename="package://fanuc_config/meshes/m_10iA/collision/link_4.stl" />
				</geometry>
				<material name="yellow"/>
			</collision>

		</link>
		<link name="${prefix}link_5">
			<visual>
				<origin
					xyz="0 0 0"
					rpy="0 0 0" />
				<geometry>
					<mesh
					  filename="package://fanuc_config/meshes/m_10iA/visual/link_5.stl" />
				</geometry>
				<material name="grey"/>
			</visual>
			<collision>
      			<origin
        			xyz="0 0 0"
        			rpy="0 0 0" />
				<geometry>
					<mesh filename="package://fanuc_config/meshes/m_10iA/collision/link_5.stl" />
				</geometry>
				<material name="yellow"/>
			</collision>

		</link>
		<link name="${prefix}link_6">
			<visual>
				<origin
					xyz="0 0 0"
					rpy="0 0 0" />
				<geometry>
					<mesh
					  filename="package://fanuc_config/meshes/m_10iA/visual/link_6.stl" />
				</geometry>
				<material name="grey"/>
			</visual>
			<collision>
      			<origin
        			xyz="0 0 0"
        			rpy="0 0 0" />
				<geometry>
					<mesh filename="package://fanuc_config/meshes/m_10iA/collision/link_6.stl" />
				</geometry>
				<material name="yellow"/>
			</collision>

		</link>
		<link name="${prefix}tool0"/>
		<!-- end of link list -->

		<!-- joint list -->
		<joint name="${prefix}joint_1" type="revolute">
			<origin
      			xyz="0 0 0"
      			rpy="0 0 0" />
			<parent
			  link="base_link" />
			<child
			  link="link_1" />
			<axis
			  xyz="0 0 1" />
			<limit
			  lower="-5.93"
			  upper="5.93"
			  effort="0"
			  velocity="3.665" />
			<calibration
			  rising="0"
			  falling="0" />
			<dynamics
			  damping="0"
			  friction="0" />
<!--			<safety_controller
			  soft_lower_limit="0"
			  soft_upper_limit="0"
			  k_position="0"
			  k_velocity="0" /> -->
		</joint>
		<joint name="${prefix}joint_2" type="revolute">
			<origin
			  xyz="0.15 -0.04 0.45"
      		  rpy="0 0 0" />
			<parent
			  link="link_1" />
			<child
			  link="link_2" />
			<axis
			  xyz="0 1 0" />
			<limit
			  lower="-4.36"
			  upper="4.36"
			  effort="0"
			  velocity="3.32" />
			<calibration
			  rising="0"
			  falling="0" />
			<dynamics
			  damping="0"
			  friction="0" />
<!--			<safety_controller
			  soft_lower_limit="0"
			  soft_upper_limit="0"
			  k_position="0"
			  k_velocity="0" /> -->
  		</joint>
		<joint name="${prefix}joint_3" type="revolute">
			<origin
			  xyz="0 -0.0225 0.6"
    		  rpy="0 0 0" />
			<parent
			  link="link_2" />
			<child
			  link="link_3" />
			<axis
			  xyz="0 1 0" />
			<limit
			  lower="-5.06"
			  upper="5.06"
			  effort="0"
			  velocity="3.665" />
			<calibration
			  rising="0"
			  falling="0" />
			<dynamics
			  damping="0"
			  friction="0" />
<!--			<safety_controller
			  soft_lower_limit="0"
			  soft_upper_limit="0"
			  k_position="0"
			  k_velocity="0" /> -->
		</joint>
		<joint name="${prefix}joint_4" type="revolute">
			<origin
			  xyz="0.1805 0.0625 0.2"
    		  rpy="0 0 0" />
			<parent
			  link="link_3" />
			<child
			  link="link_4" />
			<axis
			  xyz="1 0 0" />
			<limit
			  lower="-6.63"
			  upper="6.63"
			  effort="0"
			  velocity="6.98" />
			<calibration
			  rising="0"
			  falling="0" />
			<dynamics
			  damping="0"
			  friction="0" />
<!--			<safety_controller
			  soft_lower_limit="0"
			  soft_upper_limit="0"
			  k_position="0"
			  k_velocity="0" /> -->
		</joint>
		<joint name="${prefix}joint_5" type="revolute">
			<origin
			  xyz="0.4595 -0.0565 0"
      		  rpy="0 0 0" />
			<parent
			  link="link_4" />
			<child
			  link="link_5" />
			<axis
			  xyz="0 1 0" />
			<limit
			  lower="-6.63"
			  upper="6.63"
			  effort="0"
			  velocity="3.98" />
			<calibration
			  rising="0"
			  falling="0" />
			<dynamics
			  damping="0"
			  friction="0" />
<!--			<safety_controller
			  soft_lower_limit="0"
			  soft_upper_limit="0"
			  k_position="0"
			  k_velocity="0" /> -->
		</joint>
		<joint name="${prefix}joint_6" type="revolute">
			<origin
			  xyz="0.1 0.0565 0"
    		  rpy="0 0 0" />
			<parent
			  link="link_5" />
			<child
			  link="link_6" />
			<axis
			  xyz="1 0 0" />
			<limit
			  lower="-12.566"
			  upper="12.566"
			  effort="0"
			  velocity="10.47" />
			<calibration
			  rising="0"
			  falling="0" />
			<dynamics
			  damping="0"
			  friction="0" />
<!--			<safety_controller
			  soft_lower_limit="0"
			  soft_upper_limit="0"
			  k_position="0"
			  k_velocity="0" /> -->
		</joint>
		<joint name="${prefix}joint_6-tool0" type="fixed">
			<parent link="link_6"/>
			<child link="tool0"/>
			<origin xyz="0.1 0.0565 0" rpy="0 0 0"/>
		</joint>
		<!-- end of joint list -->
	</xacro:macro>
</robot>
